File: Correction_70-30_122023.csv
Index,Date,Time,Counter,FbLoad,Lvdt1,Lvdt2,Force(kN),Potm,LVDT1,LVDT2,Total Strain (-),Strain Alum,Strain Machine,Chain,Stress [MPa],Deviatoric Stress [Mpa],Strain Ax. [%],Strain Ax [-],Strain Al. [%],Strain Al. [-],Strain Machine [%],Strain Machine [-],Strain Rad. [%],Strain Vol. [%],Gemidd,IFlow,Ipress [Mpa],IVol,FlowA,PressA,VolA,FlowB,PressB,VolB
0,44958.41915,0,58674332,2.596803,0.07788,0.072121,2.609285,1.525493,-0.923612,-0.929118,3.13214E-05,5.2734E-05,-2.14126E-05,19.912166,3.706204,0.706204,0.197818,0.00197818,0.001008863,0.000010089,0.196809137,0.001968091,0,0.197818,-0.926365,0.00894,3,5.5234,0,3,83.7154,0,-1.6,0
32,44958.41951,31.536413,58674363,3.120969,0.084375,0.078606,3.208015,1.532395,-0.915908,-0.921558,0.00014035,6.48345E-05,7.55155E-05,19.912166,4.500474,1.500474,0.208295,0.00208295,0.002143534,0.000021435,0.206151466,0.002061515,0,0.208295,-0.918876,0.0064,3,5.5191,0,3,83.7154,0,-1.6,0
64,44958.41988,63.536413,58674395,4.274046,0.101242,0.094804,4.201965,1.547187,-0.900693,-0.907259,0.000351164,8.49223E-05,0.000266242,19.912166,6.015246,3.015246,0.230504,0.00230504,0.004307494,0.000043075,0.226196506,0.002261965,0,0.230504,-0.903671,1.71033,3,5.0527,0,3,83.7154,0,-1.6,0
96,44958.42026,95.536413,58674427,5.863592,0.119573,0.113355,5.941122,1.564937,-0.881216,-0.88757,0.000630921,0.000120071,0.00051085,19.912166,8.42353,5.42353,0.257846,0.00257846,0.0077479,0.000077479,0.2500981,0.002500981,0,0.257846,-0.884358,0.73785,3,4.4078,0,3,83.7154,0,-1.6,0
128,44958.42063,127.536413,58674459,7.792057,0.13833,0.132552,7.672574,1.582686,-0.863406,-0.869788,0.00088515,0.000155064,0.000730086,19.912166,11.012726,8.012726,0.284209,0.00284209,0.011446751,0.000114468,0.272762249,0.002727622,0,0.284209,-0.866096,0.01679,3,3.9007,0,3,83.7154,0,-1.6,0
160,44958.421,159.536413,58674491,7.100454,0.134405,0.128318,7.314893,1.580714,-0.866384,-0.87176,0.000849793,0.000147835,0.000701958,19.912166,10.273871,7.273871,0.279395,0.00279395,0.010391244,0.000103912,0.269003756,0.002690038,0,0.279395,-0.86912,0.09382,3,3.6272,0,3,83.7154,0,-1.6,0
192,44958.42137,191.536413,58674523,7.174392,0.134809,0.12915,7.341597,1.5817,-0.865932,-0.871365,0.000855843,0.000148375,0.000707468,19.912166,10.360889,7.360889,0.280306,0.00280306,0.010515556,0.000105156,0.269790444,0.002697904,0,0.280306,-0.868594,0.0529,3,3.5936,0,3,83.7154,0,-1.6,0
224,44958.42174,223.536413,58674555,7.401467,0.137705,0.131294,7.560211,1.583673,-0.86317,-0.869459,0.000889186,0.000152793,0.000736393,19.912166,10.685203,7.685203,0.283527,0.00283527,0.010978861,0.000109789,0.272548139,0.002725481,0,0.283527,-0.866303,0.03701,3,3.5719,0,3,83.7154,0,-1.6,0
256,44958.42211,255.536413,58674587,7.481547,0.137471,0.131675,7.654116,1.583673,-0.863311,-0.8689,0.000892171,0.000154691,0.000737481,19.912166,10.836923,7.836923,0.283897,0.00283897,0.011195604,0.000111956,0.272701396,0.002727014,0,0.283897,-0.866041,0.02904,3,3.5555,0,3,83.7154,0,-1.6,0
288,44958.42248,287.536413,58674619,7.549643,0.137736,0.13228,7.723133,1.583673,-0.8631,-0.868604,0.000895793,0.000156086,0.000739707,19.912166,10.929389,7.929389,0.284329,0.00284329,0.011327699,0.000113277,0.273001301,0.002730013,0,0.284329,-0.865782,0.02261,3,3.5425,0,3,83.7154,0,-1.6,0
320,44958.42285,319.536413,58674651,7.481424,0.137714,0.132016,7.707268,1.584659,-0.863129,-0.868571,0.000895821,0.000155765,0.000740056,19.912166,10.888037,7.888037,0.28422,0.0028422,0.011268624,0.000112686,0.272951376,0.002729514,0,0.28422,-0.865883,0.01966,3,3.5316,0,3,83.7154,0,-1.6,0
352,44958.42322,351.536413,58674683,7.285398,0.137696,0.131378,7.516048,1.583673,-0.863202,-0.869393,0.000889429,0.0001519,0.000737528,19.912166,10.630043,7.630043,0.283648,0.00283648,0.010900061,0.000109001,0.272747939,0.002727479,0,0.283648,-0.866284,0.01615,3,3.5223,0,3,83.7154,0,-1.6,0
384,44958.42359,383.536413,58674715,7.333028,0.137462,0.131801,7.595955,1.584659,-0.863366,-0.869097,0.000890371,0.000153515,0.000736856,19.912166,10.747367,7.747367,0.283725,0.00283725,0.011067667,0.000110677,0.272657333,0.002726573,0,0.283725,-0.866166,0.01459,3,3.5143,0,3,83.7154,0,-1.6,0
416,44958.42396,415.536413,58674747,7.957174,0.141347,0.13616,8.282168,1.588603,-0.859339,-0.864463,0.000952236,0.000167384,0.000784852,19.912166,11.705489,8.705489,0.2899,0.002899,0.012436413,0.000124364,0.277463587,0.002774636,0,0.2899,-0.861877,0.0112,3,3.5077,0,3,83.7154,0,-1.6,0
448,44958.42433,447.536413,58674779,11.733686,0.17216,0.169056,12.118021,1.62213,-0.828229,-0.831166,0.001412286,0.000244907,0.001167379,19.912166,17.117644,14.117644,0.33578,0.0033578,0.020168063,0.000201681,0.315611937,0.003156119,0,0.33578,-0.829726,0.00564,3,3.5047,0,3,83.7154,0,-1.6,0
480,44958.4247,479.536413,58674811,16.094515,0.203015,0.202287,16.474525,1.653685,-0.797683,-0.798296,0.001865257,0.000332953,0.001532304,19.912166,23.305943,20.305943,0.381172,0.00381172,0.02900849,0.000290085,0.35216351,0.003521635,0,0.381172,-0.797994,0.00367,3,3.5024,0,3,83.7154,0,-1.6,0
512,44958.42507,511.536413,58674843,21.048429,0.233254,0.235681,21.482213,1.683268,-0.767299,-0.764768,0.002321771,0.000434159,0.001887613,19.912166,30.372005,27.372005,0.426704,0.00426704,0.039102864,0.000391029,0.387601136,0.003876011,0,0.426704,-0.766163,0.0015,3,3.5011,0,2.9,83.7154,0,-1.6,0
544,44958.42544,543.536413,58674875,26.426384,0.266125,0.267463,26.931233,1.711865,-0.734343,-0.733213,0.002782564,0.000544284,0.00223828,19.912166,38.079282,35.079282,0.472996,0.00472996,0.05011326,0.000501133,0.42288274,0.004228827,0,0.472996,-0.733684,0.00017,3,3.5007,0,3,83.7154,0,-1.6,0
576,44958.42581,575.536413,58674907,31.968232,0.299073,0.297191,32.528158,1.739476,-0.701429,-0.703203,0.003232021,0.000657399,0.002574622,19.912166,45.979677,42.979677,0.517593,0.00517593,0.061399539,0.000613995,0.456193461,0.004561935,0,0.517593,-0.702407,0.00002,3,3.5006,0,3,83.7154,0,-1.6,0
608,44958.42618,607.536413,58674939,38.362182,0.33241,0.329006,38.987431,1.769059,-0.668109,-0.671615,0.00369565,0.000787942,0.002907708,19.912166,55.128934,52.128934,0.564123,0.00564123,0.074469906,0.000744699,0.489653094,0.004896531,0,0.564123,-0.66989,0,3,3.5006,0,3,83.7154,0,-1.6,0
640,44958.42655,639.536413,58674971,45.270044,0.363807,0.361369,45.957943,1.79667,-0.636771,-0.639107,0.004151693,0.000928817,0.003222876,19.912166,65.000183,62.000183,0.609694,0.00609694,0.08857169,0.000885717,0.52112231,0.005211223,0,0.609694,-0.638052,-0.00492,3,3.5015,0,2.9,83.7154,0,-1.6,0
672,44958.42692,671.536413,58675003,52.473597,0.394503,0.393573,53.284102,1.826253,-0.605835,-0.606632,0.004604629,0.00107688,0.003527749,19.912166,75.331644,72.331644,0.65494,0.0065494,0.10333092,0.001033309,0.55160908,0.005516091,0,0.65494,-0.606379,-0.00451,3,3.5055,0,3,83.7154,0,-1.6,0
704,44958.42729,703.536413,58675035,60.289127,0.426227,0.426308,61.146195,1.857808,-0.574308,-0.574156,0.005061793,0.001235774,0.003826019,19.912166,86.479181,83.479181,0.700811,0.00700811,0.119255973,0.00119256,0.581555027,0.00581555,0,0.700811,-0.57427,-0.00405,3,3.5083,0,3,83.7154,0,-1.6,0
736,44958.42766,735.536413,58675067,58.684164,0.422128,0.424256,59.506875,1.854849,-0.578768,-0.576654,0.005012093,0.001202643,0.00380945,19.912166,84.207214,81.207214,0.695932,0.00695932,0.116010306,0.001160103,0.579921694,0.005799217,0,0.695932,-0.577777,0.01529,3,3.5068,0,3,83.7154,0,-1.6,0
768,44958.42803,767.536413,58675099,50.033555,0.390339,0.391808,50.926147,1.823294,-0.610553,-0.608998,0.004554029,0.001029225,0.003524803,19.912166,72.066825,69.066825,0.65001,0.0065001,0.098666893,0.000986669,0.551343107,0.005513431,0,0.65001,-0.609831,0.01723,3,3.4964,0,3,83.7154,0,-1.6,0
800,44958.4284,799.536413,58675131,42.264078,0.359292,0.359625,43.279342,1.795684,-0.641672,-0.641342,0.004100721,0.000874682,0.003226039,19.912166,61.251846,58.251846,0.604898,0.00604898,0.083216923,0.000832169,0.521681077,0.005216811,0,0.604898,-0.641451,0.0152,3,3.488,0,3,83.7154,0,-1.6,0
832,44958.42877,831.536413,58675163,34.939255,0.327466,0.327148,36.048436,1.768073,-0.673529,-0.674015,0.003639793,0.000728544,0.002911249,19.912166,51.022971,48.022971,0.558923,0.00558923,0.068604244,0.000686042,0.490318756,0.004903188,0,0.558923,-0.673658,0.01476,3,3.4799,0,2.9,83.7154,0,-1.6,0
864,44958.42914,863.536413,58675195,28.26636,0.294671,0.295991,29.544173,1.73849,-0.706325,-0.704945,0.003184607,0.000597092,0.002587515,19.912166,41.799556,38.799556,0.513188,0.00513188,0.055427937,0.000554279,0.457760063,0.004577601,0,0.513188,-0.705606,0.01369,3,3.4722,0,3,83.7154,0,-1.6,0
896,44958.42951,895.536413,58675227,22.130256,0.26131,0.26516,23.547767,1.710879,-0.739721,-0.735876,0.002725129,0.000475904,0.002249225,19.912166,33.326826,30.326826,0.467415,0.00467415,0.043324037,0.00043324,0.424090963,0.00424091,0,0.467415,-0.737647,0.01384,3,3.4649,0,3,83.7154,0,-1.6,0
928,44958.42988,927.536413,58675259,16.679809,0.230028,0.234915,18.302564,1.681296,-0.770865,-0.765985,0.002287607,0.000369898,0.00191771,19.912166,25.882554,22.882554,0.423484,0.00423484,0.032689363,0.000326894,0.390794637,0.003907946,0,0.423484,-0.768354,0.01219,3,3.4584,0,2.9,83.7154,0,-1.6,0
960,44958.43026,959.536413,58675291,16.952277,0.23024,0.235167,18.748586,1.682282,-0.770562,-0.765525,0.002293057,0.000378912,0.001914145,19.912166,26.524683,23.524683,0.423912,0.00423912,0.03360669,0.000336067,0.39030531,0.003903053,0,0.423912,-0.768032,0.96029,3,3.1099,0,3,83.7154,0,-1.6,0
992,44958.43063,991.536413,58675323,17.925176,0.232021,0.236892,19.884852,1.685241,-0.768779,-0.764177,0.002315421,0.000401876,0.001913546,19.912166,28.198283,25.198283,0.426399,0.00426399,0.035997547,0.000359975,0.390401453,0.003904015,0,0.426399,-0.766407,1.87283,3,2.0049,0,3.1,83.7154,0,-1.6,0
1024,44958.431,1023.536413,58675355,20.290415,0.243988,0.248532,22.611853,1.696088,-0.756548,-0.751884,0.002490593,0.000456989,0.002033604,19.912166,31.952511,28.952511,0.443623,0.00443623,0.04136073,0.000413607,0.40226227,0.004022623,0,0.443623,-0.754267,0.08931,3,1.5827,0,2.9,83.7154,0,-1.6,0
1056,44958.43137,1055.536413,58675387,26.096905,0.277413,0.279297,28.66283,1.724685,-0.723093,-0.721117,0.002949321,0.00057928,0.002370041,19.912166,40.527432,37.527432,0.489473,0.00489473,0.053610617,0.000536106,0.435862383,0.004358624,0,0.489473,-0.722184,0.05004,3,1.5496,0,3,83.7154,0,-1.6,0
1088,44958.43174,1087.536413,58675419,32.309001,0.311325,0.310451,35.137066,1.753281,-0.689179,-0.690055,0.003413436,0.000710125,0.00270331,19.912166,49.691076,46.691076,0.5358,0.005358,0.066701537,0.000667015,0.469098463,0.004690985,0,0.5358,-0.689623,0.03153,3,1.5301,0,3,83.7154,0,-1.6,0
1120,44958.43211,1119.536413,58675451,38.670163,0.342987,0.341002,41.803422,1.77892,-0.65757,-0.659618,0.003856621,0.000844853,0.003011768,19.912166,59.129629,56.129629,0.580345,0.00580345,0.080185184,0.000801852,0.500159816,0.005001598,0,0.580345,-0.658596,0.02226,3,1.5165,0,3,83.7154,0,-1.6,0
1152,44958.43248,1151.536413,58675483,45.919217,0.374892,0.373524,49.345536,1.808503,-0.625648,-0.62688,0.004318479,0.000997281,0.003321198,19.912166,69.779112,66.779112,0.626348,0.00626348,0.095398731,0.000953987,0.530949269,0.005309493,0,0.626348,-0.626433,0.01546,3,1.5067,0,3,83.7154,0,-1.6,0
1184,44958.43285,1183.536413,58675515,53.758639,0.406142,0.405976,57.49631,1.838086,-0.594357,-0.594404,0.004773957,0.001162009,0.003611948,19.912166,81.310702,78.310702,0.671837,0.00671837,0.111872431,0.001118724,0.559964569,0.005599646,0,0.671837,-0.594489,0.01143,3,1.5,0,3,83.7154,0,-1.6,0
1216,44958.43322,1215.536413,58675547,61.972905,0.437732,0.438754,66.072845,1.869641,-0.562985,-0.561633,0.005232121,0.001335342,0.003896779,19.912166,93.46278,90.46278,0.717813,0.00717813,0.129232543,0.001292325,0.588580457,0.005885805,0,0.717813,-0.562365,0.00657,3,1.4957,0,3,83.7154,0,-1.6,0
1248,44958.43359,1247.536413,58675579,70.250708,0.4691,0.471409,74.733466,1.898238,-0.531391,-0.52896,0.005691171,0.001510375,0.004180797,19.912166,105.696437,102.696437,0.763598,0.00763598,0.146709196,0.001467092,0.616888804,0.006168888,0,0.763598,-0.530325,0.00338,3,1.4932,0,3,83.7154,0,-1.6,0
1280,44958.43396,1279.536413,58675611,67.298853,0.461479,0.465826,72.030132,1.891335,-0.539439,-0.534975,0.005590721,0.00145574,0.004134982,19.912166,101.928978,98.928978,0.753697,0.00753697,0.141327111,0.001413271,0.612369889,0.006123699,0,0.753697,-0.537249,0.02675,3,1.4842,0,3,83.7154,0,-1.6,0
1312,44958.43433,1311.536413,58675643,57.967101,0.429621,0.434368,63.085448,1.863724,-0.571232,-0.566531,0.005138229,0.001274966,0.003863262,19.912166,89.267062,86.267062,0.708625,0.00708625,0.12323866,0.001232387,0.58538634,0.005853863,0,0.708625,-0.5688,0.02481,3,1.4705,0,2.9,83.7154,0,-1.6,0
1344,44958.4347,1343.536413,58675675,48.96353,0.397781,0.40168,54.4505,1.833155,-0.603207,-0.5994,0.004675057,0.001100453,0.003574604,19.912166,77.058058,74.058058,0.662385,0.00662385,0.105797226,0.001057972,0.556587774,0.005565878,0,0.662385,-0.601159,0.02351,3,1.4578,0,3,83.7154,0,-1.6,0
1376,44958.43507,1375.536413,58675707,40.663593,0.367776,0.369754,46.49993,1.805545,-0.633365,-0.631448,0.004230729,0.000939771,0.003290958,19.912166,65.845023,62.845023,0.617914,0.00617914,0.089778604,0.000897786,0.528135396,0.005281354,0,0.617914,-0.63236,0.02073,3,1.4463,0,3,83.7154,0,-1.6,0
1408,44958.43544,1407.536413,58675739,32.514071,0.336137,0.335888,38.826895,1.774976,-0.664834,-0.665173,0.003765057,0.000784697,0.00298036,19.912166,54.95221,51.95221,0.571314,0.00571314,0.074217443,0.000742174,0.497096557,0.004970966,0,0.571314,-0.664964,0.02009,3,1.4354,0,3,83.7154,0,-1.6,0
1440,44958.43581,1439.536413,58675771,25.355905,0.303837,0.304803,32.134137,1.746379,-0.697082,-0.696071,0.003314014,0.000649436,0.002664579,19.912166,45.472794,42.472794,0.52614,0.0052614,0.06067542,0.000606754,0.46546458,0.004654646,0,0.52614,-0.696663,0.01807,3,1.4255,0,3,83.7154,0,-1.6,0
1472,44958.43618,1471.536413,58675803,18.824237,0.270409,0.274263,26.026846,1.718768,-0.730604,-0.726771,0.002855286,0.000526007,0.002329279,19.912166,36.836883,33.836883,0.480445,0.00480445,0.048338404,0.000483384,0.432106596,0.004321066,0,0.480445,-0.728526,0.01621,3,1.4166,0,3,83.7154,0,-1.6,0
1504,44958.43655,1503.536413,58675835,17.638092,0.266434,0.270494,25.006383,1.713837,-0.736549,-0.732523,0.002771736,0.000505383,0.002266353,19.912166,35.581832,32.581832,0.47293,0.0047293,0.046545474,0.000465455,0.426384526,0.004263845,0,0.47293,-0.73397,0.00915,3,1.4119,0,3,83.7154,0,-1.6,0
1536,44958.43692,1535.536413,58675867,16.728676,0.26272,0.267365,25.306974,1.713837,-0.736519,-0.7318,0.002777114,0.000511458,0.002265657,19.912166,35.545737,32.545737,0.47128,0.0047128,0.04649391,0.000464939,0.42478609,0.004247861,0,0.47128,-0.734583,0.00648,3,1.4086,0,3,83.7154,0,-1.6,0
1568,44958.43729,1567.536413,58675899,16.918961,0.267307,0.271124,25.357545,1.71581,-0.734994,-0.731077,0.002793171,0.00051248,0.002280692,19.912166,36.027185,33.027185,0.474813,0.00474813,0.047181693,0.000471817,0.427631307,0.004276313,0,0.474813,-0.732727,0.00521,3,1.4057,0,3,83.7154,0,-1.6,0
1600,44958.43766,1599.536413,58675931,16.406144,0.264681,0.269144,25.971851,1.71581,-0.734101,-0.729828,0.002808471,0.000524895,0.002283576,19.912166,36.516947,33.516947,0.474484,0.00474484,0.047881353,0.000478814,0.426602647,0.004266026,0,0.474484,-0.732405,0.04581,3,1.2424,0,3.1,83.7154,0,-1.6,0
1632,44958.43803,1631.536413,58675963,15.230491,0.262479,0.26717,25.115414,1.712851,-0.738351,-0.733345,0.002752993,0.000507586,0.002245407,19.912166,35.438869,32.438869,0.469801,0.00469801,0.046341241,0.000463412,0.423459759,0.004234598,0,0.469801,-0.735904,0.01387,3,1.2337,0,3,83.7154,0,-1.6,0
1664,44958.4384,1663.536413,58675995,14.829397,0.263737,0.268158,25.006985,1.712851,-0.738081,-0.733641,0.002752807,0.000505395,0.002247412,19.912166,35.465443,32.465443,0.470447,0.00470447,0.046379204,0.000463792,0.424067796,0.004240678,0,0.470447,-0.735673,0.01036,3,1.228,0,2.9,83.7154,0,-1.6,0
1696,44958.43877,1695.536413,58676027,14.507811,0.26344,0.268298,25.676802,1.714824,-0.736049,-0.73111,0.0027854,0.000518932,0.002266468,19.912166,36.166474,33.166474,0.472519,0.00472519,0.047380677,0.000473807,0.425138323,0.004251383,0,0.472519,-0.733844,0.00729,3,1.2235,0,3,83.7154,0,-1.6,0
1728,44958.43914,1727.536413,58676059,14.404331,0.266824,0.270558,25.836971,1.71581,-0.733937,-0.730124,0.002807529,0.000522169,0.002285359,19.912166,36.575903,33.575903,0.475427,0.00475427,0.047965576,0.000479656,0.427461424,0.004274614,0,0.475427,-0.732023,0.00518,3,1.2197,0,3,83.7154,0,-1.6,0
1760,44958.43951,1759.536413,58676091,13.131959,0.262738,0.267537,25.32912,1.713837,-0.737986,-0.732622,0.002760764,0.000511905,0.002248859,19.912166,35.696916,32.696916,0.47053,0.0047053,0.04670988,0.000467099,0.42382012,0.004238201,0,0.47053,-0.735467,0.00625,3,1.2158,0,3,83.7154,0,-1.6,0
1792,44958.43988,1791.536413,58676123,12.908607,0.265174,0.269334,25.167618,1.713837,-0.73761,-0.733082,0.002760164,0.000508641,0.002251523,19.912166,35.807452,32.807452,0.471482,0.00471482,0.046867789,0.000468678,0.424614211,0.004246142,0,0.471482,-0.735003,0.00692,3,1.2126,0,3,83.7154,0,-1.6,0
1824,44958.44026,1823.536413,58676155,12.569541,0.264278,0.269202,25.941405,1.71581,-0.735101,-0.730354,0.002797571,0.00052428,0.002273292,19.912166,36.584921,33.584921,0.474046,0.00474046,0.047978459,0.000479785,0.426067541,0.004260675,0,0.474046,-0.732874,0.00596,3,1.2095,0,3,83.7154,0,-1.6,0
1856,44958.44063,1855.536413,58676187,11.431869,0.262602,0.267526,25.126529,1.714824,-0.738373,-0.733378,0.0027526,0.000507811,0.002244789,19.912166,35.550486,32.550486,0.469946,0.00469946,0.046500694,0.000465007,0.423445306,0.004234453,0,0.469946,-0.73592,0.00469,3,1.2068,0,3,83.7154,0,-1.5,0
1888,44958.441,1887.536413,58676219,10.823959,0.262407,0.267271,25.02576,1.712851,-0.738892,-0.733937,0.0027449,0.000505774,0.002239126,19.912166,35.44421,32.44421,0.469391,0.00469391,0.046348871,0.000463489,0.423042129,0.004230421,0,0.469391,-0.736351,0.00379,3,1.2044,0,3,83.7154,0,-1.5,0
1920,44958.44137,1919.536413,58676251,10.416776,0.262051,0.267303,25.417003,1.713837,-0.738259,-0.73272,0.002758114,0.000513681,0.002244433,19.912166,35.826382,32.826382,0.470038,0.00470038,0.046894831,0.000468948,0.423143169,0.004231432,0,0.470038,-0.735746,0.0037,3,1.2022,0,3,83.7154,0,-1.5,0
1952,44958.44174,1951.536413,58676283,10.048515,0.264277,0.268756,25.199692,1.714824,-0.73818,-0.733542,0.002752807,0.00050929,0.002243518,19.912166,35.788869,32.788869,0.470686,0.00470686,0.046841241,0.000468412,0.423844759,0.004238448,0,0.470686,-0.73548,0.00312,3,1.2003,0,3,83.7154,0,-1.6,0
1984,44958.44211,1983.536413,58676315,9.076666,0.261368,0.266496,25.102272,1.712851,-0.739452,-0.734035,0.0027402,0.000507321,0.002232879,19.912166,35.410568,32.410568,0.46856,0.0046856,0.046300811,0.000463008,0.422259189,0.004222592,0,0.46856,-0.736833,0.00335,3,1.1982,0,3,83.7154,0,-1.5,0
2016,44958.44248,2015.536413,58676347,9.149588,0.264711,0.269249,25.439127,1.714824,-0.737249,-0.732688,0.002765557,0.000514129,0.002251429,19.912166,36.122776,33.122776,0.471924,0.00471924,0.047318251,0.000473183,0.424605749,0.004246057,0,0.471924,-0.734653,0.00341,3,1.1964,0,3,83.7154,0,-1.5,0
2048,44958.44285,2047.536413,58676379,8.827471,0.265526,0.269869,25.712983,1.71581,-0.735922,-0.731438,0.002783964,0.000519663,0.002264301,19.912166,36.440154,33.440154,0.473395,0.00473395,0.047771649,0.000477716,0.425623351,0.004256234,0,0.473395,-0.733575,0.00312,3,1.1946,0,3,83.7154,0,-1.6,0
2080,44958.44322,2079.536413,58676411,8.187507,0.263359,0.268652,25.840864,1.714824,-0.73655,-0.731373,0.002779943,0.000522248,0.002257695,19.912166,36.473436,33.473436,0.47234,0.0047234,0.047819194,0.000478192,0.424520806,0.004245208,0,0.47234,-0.734046,0.00338,3,1.1929,0,2.9,83.7154,0,-1.5,0
2112,44958.44359,2111.536413,58676443,8.117047,0.266787,0.270842,25.897575,1.716796,-0.73515,-0.730945,0.002793,0.000523394,0.002269606,19.912166,36.777109,33.777109,0.474765,0.00474765,0.048253013,0.00048253,0.426511987,0.00426512,0,0.474765,-0.732763,0.00402,3,1.1913,0,2.9,83.7154,0,-1.5,0
2144,44958.44396,2143.536413,58676475,7.019982,0.262729,0.268048,25.641076,1.714824,-0.737825,-0.732326,0.002764029,0.00051821,0.002245819,19.912166,36.193799,33.193799,0.470808,0.00470808,0.047419713,0.000474197,0.423388287,0.004233883,0,0.470808,-0.735227,0.00266,3,1.1898,0,3,83.7154,0,-1.5,0
2176,44958.44433,2175.536413,58676507,6.371726,0.262661,0.267752,25.358935,1.714824,-0.738252,-0.732983,0.002756286,0.000512508,0.002243778,19.912166,35.891891,32.891891,0.470222,0.00470222,0.046988416,0.000469884,0.423233584,0.004232336,0,0.470222,-0.735723,0.00205,3,1.1884,0,2.9,83.7154,0,-1.5,0
2208,44958.4447,2207.536413,58676539,5.97884,0.261627,0.267356,25.637843,1.713837,-0.738052,-0.732227,0.002763114,0.000518145,0.00224497,19.912166,36.126571,33.126571,0.470142,0.00470142,0.047323673,0.000473237,0.422818327,0.004228183,0,0.470142,-0.735515,0.00246,3,1.187,0,3,83.7154,0,-1.5,0
2240,44958.44507,2239.536413,58676571,6.176515,0.265984,0.270525,26.020926,1.716796,-0.734878,-0.730584,0.002797521,0.000525887,0.002271635,19.912166,36.874917,33.874917,0.47463,0.0047463,0.048392739,0.000483927,0.426237261,0.004262373,0,0.47463,-0.732662,0.00257,3,1.1859,0,3,83.7154,0,-1.5,0
2272,44958.44544,2271.536413,58676603,5.687749,0.264536,0.269588,26.308778,1.716796,-0.734628,-0.730025,0.0028033,0.000531704,0.002271596,19.912166,37.093178,34.093178,0.474525,0.00474525,0.04870454,0.000487045,0.42582046,0.004258205,0,0.474525,-0.732448,0.00306,3,1.1846,0,3,83.7154,0,-1.5,0
2304,44958.44581,2303.536413,58676635,5.038301,0.26337,0.268729,25.854676,1.714824,-0.737115,-0.731701,0.002773564,0.000522527,0.002251037,19.912166,36.534505,33.534505,0.471789,0.00471789,0.047906436,0.000479064,0.423882564,0.004238826,0,0.471789,-0.734445,0.00191,3,1.1837,0,3,83.7154,0,-1.5,0
2336,44958.44618,2335.536413,58676667,3.931006,0.260641,0.266152,25.095382,1.714824,-0.740306,-0.734627,0.002729871,0.000507181,0.00222269,19.912166,35.490287,32.490287,0.467583,0.00467583,0.046414696,0.000464147,0.421168304,0.004211683,0,0.467583,-0.737492,0.00173,3,1.1825,0,3,83.7154,0,-1.5,0
2368,44958.44655,2367.536413,58676699,4.457429,0.26392,0.269204,26.255242,1.716796,-0.735319,-0.730485,0.002795079,0.000530622,0.002264456,19.912166,37.015653,34.015653,0.473743,0.00473743,0.04859379,0.000485938,0.42514921,0.004251492,0,0.473743,-0.733174,0.00191,3,1.1814,0,3,83.7154,0,-1.5,0
2400,44958.44692,2399.536413,58676731,3.424653,0.26112,0.266805,25.423345,1.713837,-0.739701,-0.733838,0.002739829,0.00051381,0.002226019,19.912166,35.905287,32.905287,0.468615,0.00468615,0.047007553,0.000470076,0.421607447,0.004216074,0,0.468615,-0.736749,0.00205,3,1.1803,0,3,83.7154,0,-1.5,0
2432,44958.44729,2431.536413,58676763,3.342001,0.263244,0.268421,25.423928,1.714824,-0.738914,-0.733476,0.002748036,0.000513821,0.002234214,19.912166,36.11184,33.11184,0.470172,0.00470172,0.047302629,0.000473026,0.422869371,0.004228694,0,0.470172,-0.735797,0.00211,3,1.1793,0,3,83.7154,0,-1.5,0
2464,44958.44766,2463.536413,58676795,2.614107,0.261046,0.266586,25.115601,1.712851,-0.740502,-0.734824,0.002727064,0.00050759,0.002219474,19.912166,35.586273,32.586273,0.467601,0.00467601,0.046551819,0.000465518,0.421049181,0.004210492,0,0.467601,-0.737556,0.00159,3,1.1784,0,2.9,83.7154,0,-1.5,0
2496,44958.44803,2495.536413,58676827,3.027073,0.264829,0.269628,25.794747,1.716796,-0.737026,-0.731964,0.002772321,0.000521316,0.002251006,19.912166,36.625296,33.625296,0.472392,0.00472392,0.048036137,0.000480361,0.424355863,0.004243559,0,0.472392,-0.734375,0.0028,3,1.1773,0,3,83.7154,0,-1.5,0
2528,44958.4484,2527.536413,58676859,2.443254,0.263241,0.268556,25.609543,1.71581,-0.73806,-0.732819,0.002758829,0.000517573,0.002241256,19.912166,36.29581,33.29581,0.470762,0.00470762,0.047565443,0.000475654,0.423196557,0.004231966,0,0.470762,-0.73536,0.00147,3,1.1763,0,2.9,83.7154,0,-1.5,0
2560,44958.44877,2559.536413,58676891,3.030886,0.266596,0.27129,26.733858,1.718768,-0.733483,-0.728743,0.002820636,0.000540295,0.00228034,19.912166,37.755916,34.755916,0.476463,0.00476463,0.049651309,0.000496513,0.426811691,0.004268117,0,0.476463,-0.731128,0.00231,3,1.1753,0,3,83.7154,0,-1.5,0
2592,44958.44914,2591.536413,58676923,1.769997,0.262966,0.268348,25.381584,1.714824,-0.739462,-0.733805,0.002741771,0.000512966,0.002228806,19.912166,36.08876,33.08876,0.469631,0.00469631,0.047269657,0.000472697,0.422361343,0.004223613,0,0.469631,-0.736267,0.00254,3,1.1741,0,3,83.7154,0,-1.5,0
2624,44958.44951,2623.536413,58676955,2.428119,0.266714,0.271371,26.368526,1.717782,-0.734474,-0.729729,0.002806514,0.000532912,0.002273602,19.912166,37.425803,34.425803,0.475728,0.00475728,0.049179719,0.000491797,0.426548281,0.004265483,0,0.475728,-0.731952,0.00115,3,1.1731,0,3,83.7154,0,-1.5,0
2656,44958.44988,2655.536413,58676987,2.026273,0.26631,0.271047,26.115971,1.718768,-0.73585,-0.730978,0.002787764,0.000527808,0.002259957,19.912166,37.138837,34.138837,0.474471,0.00474471,0.048769767,0.000487698,0.425701233,0.004257012,0,0.474471,-0.732989,0.00159,3,1.1722,0,3,83.7154,0,-1.5,0
2688,44958.45026,2687.536413,58677019,0.562831,0.259365,0.265388,25.242466,1.712851,-0.741429,-0.734857,0.002720207,0.000510154,0.002210053,19.912166,35.672407,32.672407,0.466319,0.00466319,0.046674867,0.000466749,0.419644133,0.004196441,0,0.466319,-0.738415,0.00159,3,1.1713,0,3,83.7154,0,-1.5,0
2720,44958.45063,2719.536413,58677051,0.681534,0.261923,0.267612,25.198989,1.711865,-0.740785,-0.73512,0.002722929,0.000509275,0.002213653,19.912166,35.848308,32.848308,0.467856,0.00467856,0.046926154,0.000469262,0.420929846,0.004209298,0,0.467856,-0.737501,0.00153,3,1.1705,0,3,83.7154,0,-1.5,0
2752,44958.451,2751.536413,58677083,1.039939,0.26306,0.268574,26.36425,1.716796,-0.736153,-0.730387,0.002789821,0.000532825,0.002256996,19.912166,37.128883,34.128883,0.472761,0.00472761,0.048755547,0.000487555,0.424005453,0.004240055,0,0.472761,-0.733746,0.0011,3,1.1697,0,3,83.7154,0,-1.5,0
2784,44958.45137,2783.536413,58677115,-0.04451,0.259526,0.265439,25.32143,1.711865,-0.741325,-0.73489,0.002720714,0.00051175,0.002208964,19.912166,35.704247,32.704247,0.466355,0.00466355,0.046720353,0.000467204,0.419634647,0.004196346,0,0.466355,-0.738389,0.00101,3,1.1691,0,3,83.7154,0,-1.5,0
2816,44958.45174,2815.536413,58677147,0.686966,0.263058,0.268679,26.394486,1.716796,-0.736181,-0.730584,0.002788214,0.000533437,0.002254778,19.912166,37.199333,34.199333,0.472832,0.00472832,0.04885619,0.000488562,0.42397581,0.004239758,0,0.472832,-0.733634,0.00144,3,1.1684,0,3,83.7154,0,-1.5,0
2848,44958.45211,2847.536413,58677179,0.089363,0.26074,0.266756,25.993149,1.714824,-0.738457,-0.732589,0.002757636,0.000525325,0.00223231,19.912166,36.630608,33.630608,0.46999,0.0046999,0.048043726,0.000480437,0.421946274,0.004219463,0,0.46999,-0.735664,0.00086,3,1.1678,0,3,83.7154,0,-1.5,0
2880,44958.45248,2879.536413,58677211,-0.46957,0.259548,0.265464,25.347305,1.712851,-0.741266,-0.73535,0.00271785,0.000512273,0.002205577,19.912166,35.813488,32.813488,0.466552,0.00466552,0.046876411,0.000468764,0.419675589,0.004196756,0,0.466552,-0.738251,0.00078,3,1.1673,0,3,83.7154,0,-1.5,0
2912,44958.45285,2911.536413,58677243,-0.753478,0.258954,0.264954,25.104797,1.711865,-0.742344,-0.736369,0.002702871,0.000507372,0.0021955,19.912166,35.483861,32.483861,0.465041,0.00465041,0.046405516,0.000464055,0.418635484,0.004186355,0,0.465041,-0.739309,0.00104,3,1.1667,0,3,83.7154,0,-1.5,0
2944,44958.45322,2943.536413,58677275,-0.43237,0.259823,0.266066,25.947594,1.713837,-0.739112,-0.732852,0.002751079,0.000524405,0.002226674,19.912166,36.49866,33.49866,0.468747,0.00468747,0.047855229,0.000478552,0.420891771,0.004208918,0,0.468747,-0.736429,0.00136,3,1.1659,0,3,83.7154,0,-1.5,0
2976,44958.45359,2975.536413,58677307,0.570352,0.266248,0.271371,26.629622,1.716796,-0.734498,-0.729598,0.002807279,0.000538189,0.00226909,19.912166,37.769622,34.769622,0.475506,0.00475506,0.049670889,0.000496709,0.425835111,0.004258351,0,0.475506,-0.732004,0.00118,3,1.1653,0,3,83.7154,0,-1.5,0
3008,44958.45396,3007.536413,58677339,0.298254,0.264851,0.270377,26.770648,1.717782,-0.734856,-0.729466,0.002805664,0.000541039,0.002264625,19.912166,37.812225,34.812225,0.474957,0.00474957,0.04973175,0.000497318,0.42522525,0.004252253,0,0.474957,-0.732272,0.00072,3,1.1648,0,3,83.7154,0,-1.5,0
3040,44958.45433,3039.536413,58677371,-0.422749,0.263162,0.268817,25.741864,1.71581,-0.739065,-0.733345,0.002747893,0.000520247,0.002227646,19.912166,36.555157,33.555157,0.470225,0.00470225,0.047935939,0.000479359,0.422289061,0.004222891,0,0.470225,-0.73592,0.00005,3,1.1644,0,3,83.7154,0,-1.5,0
3072,44958.4547,3071.536413,58677403,-0.294402,0.26278,0.26851,26.469793,1.716796,-0.73672,-0.730913,0.002782014,0.000534959,0.002247056,19.912166,37.270291,34.270291,0.472051,0.00472051,0.048957559,0.000489576,0.423093441,0.004230934,0,0.472051,-0.734093,0.00179,3,1.1639,0,3,83.7154,0,-1.5,0
3104,44958.45507,3103.536413,58677435,-1.201765,0.259752,0.26582,25.246541,1.711865,-0.742091,-0.735975,0.002707493,0.000510236,0.002197256,19.912166,35.732277,32.732277,0.465539,0.00465539,0.046760396,0.000467604,0.418778604,0.004187786,0,0.465539,-0.739011,0.00112,3,1.1632,0,3,83.7154,0,-1.5,0
3136,44958.45544,3135.536413,58677467,-1.269657,0.259828,0.265897,25.243665,1.710879,-0.742133,-0.736106,0.002706257,0.000510178,0.002196079,19.912166,35.804872,32.804872,0.465855,0.00465855,0.046864103,0.000468641,0.418990897,0.004189909,0,0.465855,-0.738908,0.00069,3,1.1627,0,3,83.7154,0,-1.5,0
3168,44958.45581,3167.536413,58677499,-1.470402,0.258879,0.264988,25.262384,1.710879,-0.742316,-0.736139,0.002704714,0.000510557,0.002194158,19.912166,35.733011,32.733011,0.465226,0.00465226,0.046761444,0.000467614,0.418464556,0.004184646,0,0.465226,-0.739202,0.00028,3,1.1623,0,3,83.7154,0,-1.5,0
3200,44958.45618,3199.536413,58677531,-1.409402,0.258512,0.264954,25.640162,1.711865,-0.741516,-0.734824,0.002719821,0.000518192,0.00220163,19.912166,36.147266,33.147266,0.466074,0.00466074,0.047353237,0.000473532,0.418720763,0.004187208,0,0.466074,-0.738407,0.00052,3,1.1617,0,3.1,83.7154,0,-1.5,0
3232,44958.45655,3231.536413,58677563,-1.457156,0.258678,0.265029,25.702214,1.711865,-0.74139,-0.734627,0.002722129,0.000519446,0.002202683,19.912166,36.188367,33.188367,0.466211,0.00466211,0.047411953,0.00047412,0.418799047,0.00418799,0,0.466211,-0.738319,0.00112,3,1.1613,0,3,83.7154,0,-1.5,0
3264,44958.45692,3263.536413,58677595,-1.722855,0.257931,0.264295,25.362178,1.711865,-0.742912,-0.736172,0.002700221,0.000512573,0.002187648,19.912166,35.784688,32.784688,0.464429,0.00464429,0.046835269,0.000468353,0.417593731,0.004175937,0,0.464429,-0.73964,0.00034,3,1.1608,0,3,83.7154,0,-1.5,0
3296,44958.45729,3295.536413,58677627,-0.950942,0.262735,0.268676,25.810753,1.71581,-0.739668,-0.733772,0.002740536,0.000521639,0.002218896,19.912166,36.706635,33.706635,0.469664,0.00469664,0.048152336,0.000481523,0.421511664,0.004215117,0,0.469664,-0.736327,0.0004,3,1.1606,0,3.1,83.7154,0,-1.5,0
3328,44958.45766,3327.536413,58677659,-0.162794,0.265526,0.271227,26.905924,1.718768,-0.735145,-0.729335,0.002804536,0.000543773,0.002260763,19.912166,38.081178,35.081178,0.475066,0.00475066,0.050115969,0.00050116,0.424950031,0.0042495,0,0.475066,-0.732291,0.0015,3,1.1599,0,3,83.7154,0,-1.5,0
3360,44958.45803,3359.536413,58677691,-1.159073,0.260179,0.266522,26.224051,1.713837,-0.738908,-0.73272,0.002753479,0.000529992,0.002223487,19.912166,36.917738,33.917738,0.469155,0.00469155,0.048453911,0.000484539,0.420701089,0.004207011,0,0.469155,-0.736296,0.00023,3,1.1594,0,3,83.7154,0,-1.5,0
3392,44958.4584,3391.536413,58677723,-0.621576,0.262756,0.268816,27.221926,1.719754,-0.73402,-0.727856,0.002823136,0.000550159,0.002272976,19.912166,38.12512,35.12512,0.475157,0.00475157,0.050178743,0.000501787,0.424978257,0.004249783,0,0.475157,-0.731545,0.00141,3,1.1587,0,3,83.7154,0,-1.5,0
3424,44958.45877,3423.536413,58677755,-0.950102,0.263156,0.268982,25.830446,1.714824,-0.739919,-0.734002,0.0027371,0.000522037,0.002215063,19.912166,36.824419,33.824419,0.469844,0.00469844,0.048320599,0.000483206,0.421523401,0.004215234,0,0.469844,-0.73641,0.0002,3,1.1587,0,3,83.7154,0,-1.5,0
3456,44958.45914,3455.536413,58677787,-1.150671,0.262164,0.268138,25.723193,1.713837,-0.740601,-0.734693,0.002727293,0.00051987,0.002207423,19.912166,36.579028,33.579028,0.468427,0.00468427,0.04797004,0.0004797,0.42045696,0.00420457,0,0.468427,-0.737272,0.00115,3,1.1581,0,3,83.7154,0,-1.5,0
3488,44958.45951,3487.536413,58677819,-1.276096,0.259711,0.266101,26.280589,1.713837,-0.739025,-0.732688,0.002752871,0.000531135,0.002221737,19.912166,36.959328,33.959328,0.469079,0.00469079,0.048513326,0.000485133,0.420565674,0.004205657,0,0.469079,-0.736278,0.0004,3,1.1576,0,3,83.7154,0,-1.5,0
3520,44958.45988,3519.536413,58677851,-0.705487,0.262593,0.268862,26.803544,1.717782,-0.736535,-0.730255,0.002788036,0.000541704,0.002246332,19.912166,37.776071,34.776071,0.472833,0.00472833,0.049680101,0.000496801,0.423152899,0.004231529,0,0.472833,-0.733682,0.00069,3,1.1571,0,3,83.7154,0,-1.5,0
3552,44958.46026,3551.536413,58677883,-1.379412,0.259229,0.26595,26.199894,1.713837,-0.739722,-0.733115,0.002744843,0.000529504,0.002215339,19.912166,36.911253,33.911253,0.468404,0.00468404,0.048444647,0.000484446,0.419959353,0.004199594,0,0.468404,-0.736697,0.00075,3,1.1567,0,3,83.7154,0,-1.5,0
3584,44958.46063,3583.536413,58677915,-0.277437,0.264872,0.270897,27.193169,1.718768,-0.734577,-0.728513,0.002814464,0.000549578,0.002264886,19.912166,38.371193,35.371193,0.475533,0.00475533,0.050530276,0.000505303,0.425002724,0.004250027,0,0.475533,-0.731754,0.00063,3,1.1562,0,3,83.7154,0,-1.5,0
3616,44958.461,3615.536413,58677947,-0.222638,0.265604,0.271687,26.860571,1.718768,-0.735414,-0.729532,0.002801207,0.000542856,0.002258351,19.912166,38.154445,35.154445,0.475235,0.00475235,0.050220636,0.000502206,0.425014364,0.004250144,0,0.475235,-0.732264,0.00005,3,1.1559,0,3,83.7154,0,-1.5,0
3648,44958.46137,3647.536413,58677979,-0.430926,0.265789,0.271275,26.401049,1.718768,-0.737132,-0.731833,0.0027725,0.000533569,0.002238931,19.912166,37.621176,34.621176,0.473318,0.00473318,0.049458823,0.000494588,0.423859177,0.004238592,0,0.473318,-0.73386,0.00266,3,1.1548,0,3,83.7154,0,-1.5,0
3680,44958.46174,3679.536413,58678011,-1.211975,0.259392,0.265757,26.424482,1.713837,-0.739215,-0.73295,0.002749643,0.000534043,0.0022156,19.912166,37.174037,34.174037,0.468585,0.00468585,0.048820053,0.000488201,0.419764947,0.004197649,0,0.468585,-0.736472,0.13066,3,0.9998,0,3,83.7154,0,-1.5,0
3712,44958.46211,3711.536413,58678043,-0.105997,0.263415,0.269062,26.787865,1.713837,-0.739502,-0.734002,0.002740079,0.000541387,0.002198692,19.912166,38.149059,35.149059,0.47001,0.0047001,0.050212941,0.000502129,0.419797059,0.004197971,0,0.47001,-0.736058,4.77424,3,0.3241,0,3,83.7154,0,-1.5,0
3744,44958.46248,3743.536413,58678075,-0.19286,0.258634,0.264874,27.285531,1.711865,-0.741259,-0.734594,0.0027233,0.000551445,0.002171855,19.912166,38.416767,35.416767,0.466037,0.00466037,0.050595381,0.000505954,0.415441619,0.004154416,0,0.466037,-0.738322,0.07413,3,0,0,3,83.7154,0,-1.5,0
3776,44958.46285,3775.536413,58678107,-0.095183,0.259681,0.265582,27.131379,1.711865,-0.741093,-0.735153,0.002720493,0.000548329,0.002172164,19.912166,38.38417,35.38417,0.466662,0.00466662,0.050548814,0.000505488,0.416113186,0.004161132,0,0.466662,-0.738172,0.04978,3,0,0,3.1,83.7154,0,-1.5,0
3808,44958.46322,3807.536413,58678139,5.300495,0.286187,0.289512,32.586586,1.736518,-0.714351,-0.710862,0.003085014,0.00065858,0.002426434,19.912166,46.083386,43.083386,0.502902,0.00502902,0.061547694,0.000615477,0.441354306,0.004413543,0,0.502902,-0.712773,0.02412,3,0,0,3,83.7154,0,-1.5,0
3840,44958.46359,3839.536413,58678171,12.175428,0.319306,0.320166,39.464336,1.764128,-0.681197,-0.680129,0.00354135,0.00079758,0.00274377,19.912166,55.803921,52.803921,0.548478,0.00548478,0.075434173,0.000754342,0.473043827,0.004730438,0,0.548478,-0.680811,0.01731,3,0,0,3,83.7154,0,-1.5,0
3872,44958.46396,3871.536413,58678203,19.330178,0.350722,0.350844,46.624545,1.790753,-0.649774,-0.649593,0.003983914,0.000942289,0.003041625,19.912166,65.92278,62.92278,0.592887,0.00592887,0.089889686,0.000898897,0.502997314,0.005029973,0,0.592887,-0.649782,0.01004,3,0,0,3,83.7154,0,-1.5,0
3904,44958.46433,3903.536413,58678235,27.261449,0.383084,0.38341,54.515499,1.81935,-0.617541,-0.617117,0.004446121,0.001101766,0.003344355,19.912166,77.11112,74.11112,0.639237,0.00639237,0.105873029,0.00105873,0.533363971,0.00533364,0,0.639237,-0.617372,0.00587,3,0,0,3,83.7154,0,-1.5,0
3936,44958.4647,3935.536413,58678267,35.528077,0.415054,0.415484,62.828965,1.849919,-0.585363,-0.584872,0.004906286,0.001269783,0.003636503,19.912166,88.843589,85.843589,0.685179,0.00685179,0.122633699,0.001226337,0.562545301,0.005625453,0,0.685179,-0.585184,0.00335,3,0,0,3.1,83.7154,0,-1.5,0
3968,44958.46507,3967.536413,58678299,44.370973,0.447221,0.448072,71.629351,1.876544,-0.553358,-0.552397,0.005366857,0.00144764,0.003919217,19.912166,101.320257,98.320257,0.731272,0.00731272,0.14045751,0.001404575,0.59081449,0.005908145,0,0.731272,-0.552947,0.00092,3,0,0,3,83.7154,0,-1.5,0
4000,44958.46544,3999.536413,58678331,53.564339,0.478699,0.480704,80.848527,1.908099,-0.521839,-0.519691,0.005825607,0.001633961,0.004191646,19.912166,114.341378,111.341378,0.777002,0.00777002,0.159059111,0.001590591,0.617942889,0.006179429,0,0.777002,-0.52093,0,3,0,0,3,83.7154,0,-1.5,0
4032,44958.46581,4031.536413,58678363,62.567118,0.50995,0.512227,89.779021,1.94064,-0.490691,-0.4883,0.006272314,0.001814448,0.004457867,19.912166,127.027001,124.027001,0.821761,0.00821761,0.17718143,0.001771814,0.64457957,0.006445796,0,0.821761,-0.489557,-0.01615,3,0,0,3,83.7154,0,-1.5,0
4064,44958.46618,4063.536413,58678395,52.672314,0.477849,0.482538,79.845647,1.908099,-0.52313,-0.518508,0.005824836,0.001613693,0.004211143,19.912166,112.981387,109.981387,0.77748,0.0077748,0.157116267,0.001571163,0.620363733,0.006203637,0,0.77748,-0.520742,0.02218,3,0,0,3,83.7154,0,-1.5,0
4096,44958.46655,4095.536413,58678427,43.138721,0.445375,0.450152,70.298272,1.878516,-0.555594,-0.550819,0.005362157,0.001420739,0.003941418,19.912166,99.493484,96.493484,0.730947,0.00730947,0.137847834,0.001378478,0.593099166,0.005930992,0,0.730947,-0.553257,0.01885,3,0,0,3,83.7154,0,-1.5,0
4128,44958.46692,4127.536413,58678459,34.795208,0.414826,0.419688,61.944657,1.852877,-0.586196,-0.581519,0.004924286,0.001251911,0.003672375,19.912166,87.689979,84.689979,0.687381,0.00687381,0.120985684,0.001209857,0.566395316,0.005663953,0,0.687381,-0.583671,0.01725,3,0,0,3,83.7154,0,-1.5,0
4160,44958.46729,4159.536413,58678491,25.865634,0.381954,0.3856,53.079028,1.820336,-0.618983,-0.615375,0.004448264,0.001072735,0.003375529,19.912166,75.107935,72.107935,0.639693,0.00639693,0.103011336,0.001030113,0.536681664,0.005366817,0,0.639693,-0.617104,0.01902,3,0,0,3,83.7154,0,-1.5,0
4192,44958.46766,4191.536413,58678523,18.043456,0.35219,0.353417,45.231046,1.791739,-0.648908,-0.647883,0.004002314,0.000914126,0.003088188,19.912166,64.045645,61.045645,0.595121,0.00595121,0.087208064,0.000872081,0.507912936,0.005079129,0,0.595121,-0.648328,0.01621,3,0,0,3,83.7154,0,-1.5,0
4224,44958.46803,4223.536413,58678555,10.563038,0.320606,0.321198,37.825723,1.762156,-0.680644,-0.679931,0.003546714,0.000764464,0.002782251,19.912166,53.5589,50.5589,0.549536,0.00549536,0.072227,0.00072227,0.477309,0.00477309,0,0.549536,-0.680162,0.01549,3,0,0,3,83.7154,0,-1.5,0
4256,44958.4684,4255.536413,58678587,5.376427,0.294511,0.296519,32.830863,1.740462,-0.706199,-0.704091,0.003191607,0.000663517,0.00252809,19.912166,46.442,43.442,0.513786,0.00513786,0.06206,0.0006206,0.451726,0.00451726,0,0.513786,-0.705187,0.00981,3,0,0,3,83.7154,0,-1.5,0
4288,44958.46877,4287.536413,58678619,6.545934,0.296199,0.297002,34.048795,1.740462,-0.704829,-0.703729,0.003203979,0.000688131,0.002515847,19.912166,48.190703,45.190703,0.515095,0.00515095,0.064558147,0.000645581,0.450536853,0.004505369,0,0.515095,-0.704273,0.77726,3,0,0,3,83.7154,0,-1.5,0
4320,44958.46914,4319.536413,58678651,7.310031,0.296906,0.297358,34.995671,1.740462,-0.703642,-0.703269,0.003215743,0.000707268,0.002508475,19.912166,49.490144,46.490144,0.516273,0.00516273,0.066414491,0.000664145,0.449858509,0.004498585,0,0.516273,-0.70342,0.14305,3,0,0,3,83.7154,0,-1.5,0
4352,44958.46951,4351.536413,58678683,14.425894,0.3289,0.328075,42.235881,1.771031,-0.671731,-0.672503,0.003663436,0.000853594,0.002809842,19.912166,59.724821,56.724821,0.560881,0.00560881,0.081035459,0.000810355,0.479845541,0.004798455,0,0.560881,-0.672071,0.043,3,0,0,3,83.7154,0,-1.5,0
4384,44958.46988,4383.536413,58678715,22.068334,0.361092,0.360326,50.020677,1.799628,-0.63945,-0.640027,0.004125986,0.001010925,0.00311506,19.912166,70.732509,67.732509,0.60709,0.0060709,0.096760727,0.000967607,0.510329273,0.005103293,0,0.60709,-0.639875,0.03029,3,0,0,3,83.7154,0,-1.5,0
4416,44958.47026,4415.536413,58678747,30.314104,0.393708,0.393736,58.46611,1.828225,-0.606849,-0.606566,0.004597857,0.001181609,0.003416248,19.912166,82.676773,79.676773,0.654187,0.00654187,0.113823961,0.00113824,0.540363039,0.00540363,0,0.654187,-0.606767,0.01859,3,0,0,3,83.7154,0,-1.5,0
4448,44958.47063,4447.536413,58678779,38.486833,0.424602,0.424725,66.810413,1.856822,-0.57601,-0.575866,0.005037421,0.001350249,0.003687173,19.912166,94.501975,91.501975,0.698355,0.00698355,0.130717107,0.001307171,0.567637893,0.005676379,0,0.698355,-0.57594,0.01201,3,0,0,3,83.7154,0,-1.5,0
4480,44958.471,4479.536413,58678811,47.559674,0.45731,0.457632,76.106471,1.886405,-0.543242,-0.5427,0.005508379,0.001538123,0.003970255,19.912166,107.628656,104.628656,0.745344,0.00745344,0.149469509,0.001494695,0.595874491,0.005958745,0,0.745344,-0.54303,0.00625,3,0,0,3,83.7154,0,-1.5,0
4512,44958.47137,4511.536413,58678843,57.461066,0.49061,0.492578,86.288096,1.919932,-0.509776,-0.507562,0.005998407,0.001743895,0.004254512,19.912166,122.024871,119.024871,0.794289,0.00794289,0.17003553,0.001700355,0.62425347,0.006242535,0,0.794289,-0.50874,0.0055,3,0,0,3.1,83.7154,0,-1.5,0
4544,44958.47174,4543.536413,58678875,66.148878,0.520422,0.522072,95.146663,1.947543,-0.480165,-0.478472,0.0064177,0.001922928,0.004494772,19.912166,134.586509,131.586509,0.836363,0.00836363,0.187980727,0.001879807,0.648382273,0.006483823,0,0.836363,-0.479383,0.00286,3,0,0,3,83.7154,0,-1.5,0
4576,44958.47211,4575.536413,58678907,65.026942,0.519256,0.522741,94.196555,1.948529,-0.481562,-0.477946,0.006411479,0.001903727,0.004507752,19.912166,133.278471,130.278471,0.835797,0.00835797,0.186112101,0.001861121,0.649684899,0.006496849,0,0.835797,-0.47978,0.02797,3,0,0,3,83.7154,0,-1.5,0
4608,44958.47248,4607.536413,58678939,55.429537,0.488169,0.493343,84.852361,1.919932,-0.512684,-0.507529,0.005977871,0.001714879,0.004262992,19.912166,120.061242,117.061242,0.792577,0.00792577,0.167230346,0.001672303,0.625346654,0.006253467,0,0.792577,-0.510034,0.02397,3,0,0,3,83.7154,0,-1.5,0
4640,44958.47285,4639.536413,58678971,45.229783,0.455047,0.459757,74.898934,1.887391,-0.5459,-0.540925,0.005502071,0.001513719,0.003988353,19.912166,105.973657,102.973657,0.744944,0.00744944,0.147105224,0.001471052,0.597838776,0.005978388,0,0.744944,-0.543377,0.02574,3,0,0,3,83.7154,0,-1.5,0
4672,44958.47322,4671.536413,58679003,36.50124,0.424835,0.429722,66.433036,1.861752,-0.576066,-0.571198,0.005070364,0.001342622,0.003727743,19.912166,94.008389,91.008389,0.701837,0.00701837,0.130011984,0.00130012,0.571825016,0.00571825,0,0.701837,-0.573591,0.01937,3,0,0,3,83.7154,0,-1.5,0
4704,44958.47359,4703.536413,58679035,27.535305,0.393329,0.397595,57.768026,1.831183,-0.607554,-0.603378,0.004615593,0.001167501,0.003448092,19.912166,81.753916,78.753916,0.656394,0.00656394,0.112505594,0.001125056,0.543888406,0.005438884,0,0.656394,-0.605432,0.01969,3,0,0,3,83.7154,0,-1.5,0
4736,44958.47396,4735.536413,58679067,18.747386,0.361659,0.36367,49.252001,1.8016,-0.639256,-0.637266,0.004147093,0.00099539,0.003151702,19.912166,69.699611,66.699611,0.609536,0.00609536,0.095285159,0.000952852,0.514250841,0.005142508,0,0.609536,-0.638163,0.02015,3,0,0,3,83.7154,0,-1.5,0
4768,44958.47433,4767.536413,58679099,10.958408,0.331714,0.332123,41.81797,1.772017,-0.669342,-0.668953,0.003705857,0.000845148,0.00286071,19.912166,59.190577,56.190577,0.565376,0.00565376,0.080272253,0.000802723,0.485103747,0.004851037,0,0.565376,-0.669075,0.01731,3,0,0,3,83.7154,0,-1.5,0
4800,44958.4747,4799.536413,58679131,7.426634,0.31619,0.316259,38.725381,1.758212,-0.684623,-0.684533,0.003485421,0.000782646,0.002702776,19.912166,54.778495,51.778495,0.543352,0.00543352,0.073969279,0.000739693,0.469382721,0.004693827,0,0.543352,-0.684473,1.4914,3,0,0,3,83.7154,0,-1.5,0
4832,44958.47507,4831.536413,58679163,8.235508,0.31713,0.316994,39.183493,1.757226,-0.687029,-0.687261,0.00344875,0.000791904,0.002656846,19.912166,55.714463,52.714463,0.540846,0.00540846,0.075306376,0.000753064,0.465539624,0.004655396,0,0.540846,-0.686702,1.52039,3,0,0,3.1,83.7154,0,-1.5,0
4864,44958.47544,4863.536413,58679195,12.858524,0.335532,0.333502,44.934504,1.774976,-0.665052,-0.667112,0.00374965,0.000908133,0.002841517,19.912166,63.558493,60.558493,0.569498,0.00569498,0.086512133,0.000865121,0.482985867,0.004829859,0,0.569498,-0.666039,0.06014,3,0,0,3,83.7154,0,-1.5,0
4896,44958.47581,4895.536413,58679227,20.272612,0.366008,0.365027,52.787678,1.803572,-0.634578,-0.635557,0.004192714,0.001066847,0.003125867,19.912166,74.643478,71.643478,0.613943,0.00613943,0.102347826,0.001023478,0.511595174,0.005115952,0,0.613943,-0.635029,0.0335,3,0,0,3,83.7154,0,-1.5,0
4928,44958.47618,4927.536413,58679259,28.615336,0.398859,0.398796,61.538283,1.832169,-0.601613,-0.601866,0.004668829,0.001243698,0.003425131,19.912166,87.032401,84.032401,0.661603,0.00661603,0.120046287,0.001200463,0.541556713,0.005415567,0,0.661603,-0.601715,0.01977,3,0,0,3,83.7154,0,-1.5,0
4960,44958.47655,4959.536413,58679291,36.579019,0.429603,0.429637,69.950307,1.861752,-0.571093,-0.570836,0.005108471,0.001413706,0.003694765,19.912166,98.937695,95.937695,0.705414,0.00705414,0.13705385,0.001370539,0.56836015,0.005683602,0,0.705414,-0.570933,0.01303,3,0,0,3,83.7154,0,-1.5,0
4992,44958.47692,4991.536413,58679323,45.982896,0.463432,0.464026,79.787872,1.892321,-0.537093,-0.53652,0.005596443,0.001612525,0.003983918,19.912166,112.852165,109.852165,0.754334,0.00754334,0.156931664,0.001569317,0.597402336,0.005974023,0,0.754334,-0.536782,0.00926,3,0,0,3,83.7154,0,-1.5,0
5024,44958.47729,5023.536413,58679355,54.922358,0.494309,0.495954,89.211842,1.92289,-0.506223,-0.504505,0.006045621,0.001802985,0.004242637,19.912166,126.182032,123.182032,0.799201,0.00799201,0.175974331,0.001759743,0.623226669,0.006232267,0,0.799201,-0.505383,0.00498,3,0,0,3,83.7154,0,-1.5,0
5056,44958.47766,5055.536413,58679387,63.690934,0.524343,0.525831,98.453432,1.952473,-0.476135,-0.474824,0.006472543,0.001989759,0.004482784,19.912166,139.25536,136.25536,0.842056,0.00842056,0.194650514,0.001946505,0.647405486,0.006474055,0,0.842056,-0.475448,0.00359,3,0,0,3,83.7154,0,-1.5,0
5088,44958.47803,5087.536413,58679419,65.164807,0.532355,0.535036,100.301529,1.959376,-0.46853,-0.46585,0.006590964,0.002027109,0.004563855,19.912166,141.932483,138.932483,0.853871,0.00853871,0.198474976,0.00198475,0.655396024,0.00655396,0,0.853871,-0.467175,0.03344,3,0,0,3,83.7154,0,-1.5,0
5120,44958.4784,5119.536413,58679451,54.573364,0.498774,0.503891,90.162854,1.929793,-0.502011,-0.496748,0.006131114,0.001822205,0.004308909,19.912166,127.581364,124.581364,0.807662,0.00807662,0.177973377,0.001779734,0.629688623,0.006296886,0,0.807662,-0.499481,0.02933,3,0,0,3,83.7154,0,-1.5,0
5152,44958.47877,5151.536413,58679483,44.504308,0.466967,0.472335,80.548,1.899224,-0.533961,-0.528632,0.005675157,0.001627887,0.00404727,19.912166,113.984691,110.984691,0.762247,0.00762247,0.158549559,0.001585496,0.603697441,0.006036974,0,0.762247,-0.531288,0.02406,3,0,0,3,83.7154,0,-1.5,0
5184,44958.47914,5183.536413,58679515,34.725787,0.435177,0.43991,71.256914,1.869641,-0.565697,-0.56091,0.005217914,0.001440113,0.003777801,19.912166,100.830706,97.830706,0.7165,0.007165,0.139758151,0.001397582,0.576741849,0.005767418,0,0.7165,-0.563299,0.02421,3,0,0,3,83.7154,0,-1.5,0
5216,44958.47951,5215.536413,58679547,25.772762,0.404765,0.409397,62.753292,1.843016,-0.596266,-0.591577,0.004780514,0.001268254,0.003512261,19.912166,88.820185,85.820185,0.67282,0.0067282,0.122600264,0.001226003,0.550219736,0.005502197,0,0.67282,-0.593864,0.01989,3,0,0,3,83.7154,0,-1.5,0
5248,44958.47988,5247.536413,58679579,16.337086,0.37138,0.374934,53.853675,1.813433,-0.629524,-0.625992,0.004297136,0.001088391,0.003208745,19.912166,76.20607,73.20607,0.624491,0.00624491,0.1045801,0.001045801,0.5199109,0.005199109,0,0.624491,-0.627778,0.02221,3,0,0,3,83.7154,0,-1.5,0
5280,44958.48026,5279.536413,58679611,7.886679,0.341578,0.34207,45.889448,1.781878,-0.659309,-0.65873,0.003850543,0.000927433,0.00292311,19.912166,64.946293,61.946293,0.579815,0.00579815,0.088494704,0.000884947,0.491320296,0.004913203,0,0.579815,-0.659022,0.02061,3,0,0,3,83.7154,0,-1.5,0
5312,44958.48063,5311.536413,58679643,2.285334,0.320115,0.320211,40.857348,1.764128,-0.680678,-0.680392,0.003543179,0.000825733,0.002717445,19.912166,57.811284,54.811284,0.548886,0.00548886,0.078301834,0.000783018,0.470584166,0.004705842,0,0.548886,-0.680634,0.00781,3,0,0,3,83.7154,0,-1.5,0
5344,44958.481,5343.536413,58679675,1.969151,0.320256,0.320339,41.042805,1.764128,-0.680522,-0.68026,0.003545236,0.000829481,0.002715754,19.912166,58.063963,55.063963,0.548997,0.00548997,0.078662804,0.000786628,0.470334196,0.004703342,0,0.548997,-0.68054,0.00616,3,0,0,3,83.7154,0,-1.5,0
5376,44958.48137,5375.536413,58679707,1.404851,0.320124,0.320172,41.035969,1.762156,-0.680631,-0.680622,0.003541871,0.000829343,0.002712528,19.912166,58.056337,55.056337,0.549066,0.00549066,0.07865191,0.000786519,0.47041409,0.004704141,0,0.549066,-0.68062,0.00616,3,0,0,3,83.7154,0,-1.5,0
5408,44958.48174,5407.536413,58679739,0.925812,0.32037,0.320349,41.089408,1.763142,-0.680416,-0.680227,0.003546229,0.000830423,0.002715805,19.912166,58.129749,55.129749,0.549224,0.00549224,0.078756784,0.000787568,0.470467216,0.004704672,0,0.549224,-0.680381,0.005,3,0,0,3,83.7154,0,-1.5,0
5440,44958.48211,5439.536413,58679771,0.231424,0.320344,0.32052,40.935914,1.763142,-0.680431,-0.680326,0.003545414,0.000827321,0.002718093,19.912166,57.924275,54.924275,0.5493,0.005493,0.07846325,0.000784633,0.47083675,0.004708368,0,0.5493,-0.680257,-4.51186,3,0,0,3,83.7154,0,-1.5,0
5449,44958.48221,5448.536413,58679780,-0.149361,0.320691,0.320923,40.71234,1.764128,-0.680079,-0.6798,0.003551686,0.000822803,0.002728883,19.912166,57.606158,54.606158,0.549939,0.00549939,0.078008797,0.000780088,0.471930203,0.004719302,0,0.549939,-0.679939,0.24962,3,0,0,3,83.7154,0,-1.5,0